Workbook

Sheet Division Incrementos
A3: Incremento | B3: Porcentaje | C3: Porcentaje Acumulado | D3: Cantidad de Casos de Uso
A4: 1 | B4: =D4/$C$9 -> 0.23287671 | C4: =B4 -> 0.23287671 | D4: =COUNTIF('ProductSprint Backlog'!B:B, 1) -> 17
A5: 2 | B5: =D5/$C$9 -> 0.57534247 | C5: =C4+B5 -> 0.80821918 | D5: =COUNTIF('ProductSprint Backlog'!B:B, 2) +COUNTIF('ProductSprint Backlog'!B:B, 3) -> 42
A6: 3 | B6: =D6/$C$9 -> 0.16438356 | C6: =C5+B6 -> 0.97260274 | D6: =COUNTIF('ProductSprint Backlog'!B:B, 4) -> 12
A7: 4 | B7: =D7/$C$9 -> 0.02739726 | C7: =C6+B7 -> 1 | D7: =COUNTIF('ProductSprint Backlog'!B:B, 5) -> 2
E8: =SUM(D4:D7) -> 73
B9: Total CU | C9: =E8 -> 73

Sheet ProductSprint Backlog
B1: Product Backlog | I1: Estimado | K1: Real | M1: Proyecto
A2: Incremento | B2: Sprint | C2: Caso de Uso Extendido | D2: Actividades | E2: Responsable | F2: Estimar HH | G2: Estado | H2: Objetivo del Sprint | I2: Inicio | J2: Fin | K2: Inicio | L2: Fin | M2: HH Efectivas
A3: 1 | B3: 1 | C3: 8.1.1 Iniciando sesión en el sistema | D3: Diseñar y desarrollar el formulario de login. | E3: Geronimo Lopez | F3: 5 | G3: Terminado | H3: Realizar el diseño del login junto con sus conexiones y llamadas a la BD | I3: 45806 | J3: 45812 | K3: 45806 | L3: 45812 | M3: 4.5
D4: Implementar validación de formato y de credenciales contra base de datos. | E4: Geronimo Lopez | F4: 3 | G4: Terminado | H4: Aplicar las validaciones de formato para correo y pwd, junto con las de credenciales | I4: 45808 | J4: 45813 | K4: 45809 | L4: 45813 | M4: 2
D5: Redireccionar a vista según rol del usuario. | E5: Geronimo Lopez | F5: 2 | G5: Terminado | H5: Redireccionar a la vista del rol definido en la BD, inmediatamente después de ingresar | I5: 45810 | J5: 45811 | K5: 45810 | L5: 45812 | M5: 1.5
D6: Registrar evento de inicio de sesión en logs. | E6: Geronimo Lopez | F6: 2 | G6: Terminado | H6: Guardar en los logs de auditoría y en la info interna de usuarios, los registros de inicio de sesión | I6: 45813 | J6: 45818 | K6: 45813 | L6: 45816 | M6: 2
A8: 1 | B8: 1 | C8: 8.2.1 Recuperando contraseña olvidada | D8: Diseñar botón y flujo de “¿Olvidó su contraseña?”. | E8: Geronimo Lopez | F8: 1 | G8: Terminado | H8: Agregar al diseño del login la entrada al flujo del recuperacion de contraseña, y diseñar el flujo correspondiente | I8: 45810 | J8: 45812 | K8: 45811 | L8: 45812 | M8: 1.5
D9: Implementar validación de existencia del correo electrónico. | E9: Geronimo Lopez | F9: 2 | G9: Terminado | H9: Consultar en la BD si existe el correo de la persona que quiere recuperar contraseña | I9: 45810 | J9: 45812 | K9: 45812 | L9: 45813 | M9: 1
D10: Generar contraseña temporal de recuperación. | E10: Geronimo Lopez | F10: 3 | G10: Terminado | H10: Generar la password, que sea segura al ser una combinación de número, letras y caracteres especiales | I10: 45811 | J10: 45813 | K10: 45812 | L10: 45813 | M10: 3
D11: Enviar correo con la contraseña temporal. | E11: Geronimo Lopez | F11: 3 | G11: Terminado | H11: Diseñar y enviar el mensaje con la nueva contraseña al correo de la persona | I11: 45811 | J11: 45814 | K11: 45813 | L11: 45814 | M11: 3
D12: Validar contraseña y permitir ingreso con nueva contraseña. | E12: Geronimo Lopez | F12: 2 | G12: Terminado | H12: Realizar el cambio de pwd en la BD, y así validar cuando entre con la contraseña nueva | I12: 45812 | J12: 45814 | K12: 45814 | L12: 45815 | M12: 2
G13: Terminado
A14: 1 | B14: 1 | C14: 8.3.1 Expirando sesión tras 16 horas | D14: Registrar hora de inicio de sesión. | E14: Geronimo Lopez | F14: 2 | G14: Terminado | H14: Cuando inicie sesión la persona, tomar un timestamp del momento en que ingresó | I14: 45813 | J14: 45815 | K14: 45815 | L14: 45816 | M14: 1
D15: Implementar monitoreo de duración de sesión. | E15: Geronimo Lopez | F15: 4 | G15: Terminado | H15: Hacer que el sistema sea capaz de monitorear la sesión, sabiendo su tiempo de sesión actual | I15: 45813 | J15: 45815 | K15: 45815 | L15: 45817 | M15: 4.5
D16: Forzar cierre de sesión a las 16 horas. | E16: Geronimo Lopez | F16: 3 | G16: Terminado | H16: En base al monitoreo, forzar salida de sesión cuando se detecten las 16 horas | I16: 45815 | J16: 45818 | K16: 45816 | L16: 45818 | M16: 2
D17: Mostrar mensaje de expiración y redirigir al login. | E17: Geronimo Lopez | F17: 2 | G17: Terminado | H17: Cuando suceda lo anterior, mostrar un mensaje al usuario y redirigir a la vista de inicio de sesión | I17: 45817 | J17: 45818 | K17: 45818 | L17: 45819 | M17: 1
A19: 1 | B19: 1 | C19: 4.1.1 Registrando un nuevo equipo (Registro) | D19: Diseñar formulario de registro de equipo (marca, modelo, número de serie, tipo, descripción, cliente). | E19: Samir Saud | F19: 6 | G19: Terminado | H19: Diseñar el formulario del registro de equipo para el proceso de reparación, incluyendo los campos mencionados | I19: 45806 | J19: 45812 | K19: 45808 | L19: 45814 | M19: 5.5
D20: Validar que el número de serie no exista en la base de datos y los campos obligatorios. | E20: Samir Saud | F20: 3 | G20: Terminado | H20: Revisar el número de serie al momento de ser ingresado, para decidir si ir a CU 4.2.1, luego validar los otros campos | I20: 45808 | J20: 45810 | K20: 45809 | L20: 45810 | M20: 2
D21: Registrar equipo y asociarlo al cliente (usar cliente único durante entorno de desarrollo). | E21: Samir Saud | F21: 2 | G21: Terminado | H21: Registrar lo ingresado en el formulario en la base de datos, vinculando a un cliente en la BD (usar un cliente estático en desarrollo) | I21: 45811 | J21: 45814 | K21: 45811 | L21: 45812 | M21: 3
D22: Generar automáticamente una orden de trabajo inicial y almacenarla | E22: Samir Saud | F22: 3 | G22: Terminado | H22: Generar la orden de trabajo con los datos ingresados, almacenarlo en la BD | I22: 45812 | J22: 45814 | K22: 45812 | L22: 45814 | M22: 2
A24: 1 | B24: 1 | C24: 4.2.1 Generando orden de trabajo asociada a equipo ya ingresado (Registro) | D24: Detectar qué equipo ya está registrado al ingresar el número de serie. | E24: Samir Saud | F24: 1 | G24: Terminado | H24: Detectar que el número de serie ingresado ya existe en la BD | I24: 45808 | J24: 45809 | K24: 45808 | L24: 45809 | M24: 1
D25: Autocompletar datos del equipo y cliente al acceder, y notificar al usuario de que se encontró un equipo ya existente | E25: Samir Saud | F25: 3 | G25: Terminado | H25: Luego, consultar en la BD la info del equipo, utilizando los datos para autocompletar el formulario, para luego notificar al usuario de que ya existe el equipo | I25: 45808 | J25: 45812 | K25: 45810 | L25: 45812 | M25: 3.5
D26: Generar orden de trabajo (número único, estado “Recibido”) y almacenarla | E26: Samir Saud | F26: 2 | G26: Terminado | H26: Generar una nueva orden de trabajo con los datos ingresados, almacenarlo en la BD | I26: 45812 | J26: 45814 | K26: 45812 | L26: 45814 | M26: 1
A28: 1 | B28: 1 | C28: 4.3.1 Mostrando alerta de registro exitoso de equipo (Registro) | D28: Diseñar e implementar alerta visual (popup o toast) para mensaje de éxito. | E28: Samir Saud | F28: 1 | G28: Terminado | H28: Diseñar una alerta visual para cuando se genera la orden | I28: 45813 | J28: 45815 | K28: 45814 | L28: 45816 | M28: 1
D29: Incluir en el mensaje: “Equipo registrado exitosamente” y “Orden de trabajo generada con número: [ID]” y otra información relevante. | E29: Samir Saud | F29: 1 | G29: Terminado | H29: Agregar la información pertinente al equipo y la orden de trabajo en la alerta visual diseñada | I29: 45813 | J29: 45815 | K29: 45815 | L29: 45815 | M29: 0.5
D30: Asegurar que la alerta se active automáticamente tras registrar equipo y generar orden. | E30: Samir Saud | F30: 1 | G30: Terminado | H30: Luego de 4.1.1 o 4.2.1, hacer que el sistema muestre la alerta diseñada | I30: 45814 | J30: 45815 | K30: 45815 | L30: 45816 | M30: 1
A32: 1 | B32: 1 | C32: 2.1.1 Visualizando información principal de los equipos (Laboratorio) | D32: Crear vista para técnicos del laboratorio con listado de equipos | E32: Bastian Benitez | F32: 3 | G32: Terminado | H32: Crear la vista genera de Gestión de Órdenes del personal de laboratorio | I32: 45807 | J32: 45810 | K32: 45807 | L32: 45810 | M32: 3
D33: Mostrar campos: marca, modelo, cliente, estado, prioridad, fecha de ingreso. | E33: Bastian Benitez | F33: 2 | G33: Terminado | H33: Incluir en esa vista la información del equipo y orden más importante para el rol | I33: 45809 | J33: 45811 | K33: 45809 | L33: 45810 | M33: 2
D34: Mostrar los botones de interacción: ver informe, ver cotizacion, crear cotización, ver historial de equipo y crear informe | E34: Bastian Benitez | F34: 2 | G34: Terminado | H34: Agregar los botones de interacción posibles, solo visualmente, la funcionalidad se integra cuando las secciones correspondientes estén listas | I34: 45810 | J34: 45811 | K34: 45810 | L34: 45811 | M34: 1
D35: Asegurar actualización en tiempo real o con recarga controlada | E35: Bastian Benitez | F35: 2 | G35: Terminado | H35: Implementar que el sistema actualice en tiempo real (o pseudoreal, con un timer corto) los cambio en la BD de los equipos y órdenes | I35: 45810 | J35: 45811 | K35: 45810 | L35: 45811 | M35: 1
A37: 1 | B37: 1 | C37: 3.1.1 Visualizando información principal de los equipos (Recepción) | D37: Crear vista para recepción con listado de equipos | E37: Bastian Benitez | F37: 3 | G37: Terminado | H37: Crear la vista genera de Gestión de Órdenes del personal de laboratorio | I37: 45810 | J37: 45811 | K37: 45810 | L37: 45810 | M37: 2
D38: Mostrar marca, modelo, cliente, estado actual, prioridad y fecha. | E38: Bastian Benitez | F38: 2 | G38: Terminado | H38: Incluir en esa vista la información del equipo y orden más importante para el rol | I38: 45810 | J38: 45811 | K38: 45810 | L38: 45811 | M38: 1
D39: Mostrar los botones de interacción: ver informe, ver cotización, aprobar cotizacion, rechazar cotizacion y ver historial de equipo | E39: Bastian Benitez | F39: 2 | G39: Terminado | H39: Agregar los botones de interacción posibles, solo visualmente, la funcionalidad se integra cuando las secciones correspondientes estén listas | I39: 45811 | J39: 45812 | K39: 45811 | L39: 45811 | M39: 1
D40: Asegurar actualización en tiempo real o con recarga controlada | E40: Bastian Benitez | F40: 2 | G40: Terminado | H40: Implementar que el sistema actualice en tiempo real (o pseudoreal, con un timer corto) los cambio en la BD de los equipos y órdenes | I40: 45812 | J40: 45813 | K40: 45811 | L40: 45811 | M40: 1
A42: 1 | B42: 1 | C42: 2.2.1 Visualizando Informe Técnico de un Equipo (Laboratorio) | D42: Habilitar opción “Visualizar Informe Técnico” solo si el informe existe. | E42: Manuel Vidal | F42: 1 | G42: Terminado | H42: Activar el botón cuando el campo de la BD de la orden tenga un informe relacionado | I42: 45815 | J42: 45817 | K42: 45816 | L42: 45817 | M42: 1
D43: Mostrar contenido del informe en vista interna legible. | E43: Manuel Vidal | F43: 3 | G43: Terminado | H43: Al presionar el botón, aparezca una vista del informe técnico (no necesariamente PDF), con los datos guardados en la BD | I43: 45816 | J43: 45818 | K43: 45816 | L43: 45818 | M43: 4
A45: 1 | B45: 1 | C45: 2.2.2 Visualizando Cotización de un Equipo(Laboratorio) | D45: Habilitar opción “Visualizar Cotizacion” solo si la Cotización existe. | E45: Eliam Rivas | F45: 1 | G45: Terminado | H45: Activar el botón cuando el campo de la BD de la orden tenga una cotización relacionada | I45: 45815 | J45: 45817 | K45: 45815 | L45: 45817 | M45: 1
D46: Mostrar contenido de la cotización en vista interna legible. | E46: Eliam Rivas | F46: 3 | G46: Terminado | H46: Al presionar el botón, aparezca una vista de cotización (no necesariamente PDF), con los datos guardados en la BD | I46: 45816 | J46: 45818 | K46: 45816 | L46: 45818 | M46: 3
A48: 1 | B48: 1 | C48: 3.2.1 Visualizando Informe Técnico de un equipo (Recepción) | D48: Habilitar opción “Visualizar Informe Técnico” solo si el informe existe. | E48: Manuel Vidal | F48: 1 | G48: Terminado | H48: Activar el botón cuando el campo de la BD de la orden tenga un informe relacionado | I48: 45815 | J48: 45817 | K48: 45816 | L48: 45816 | M48: 0.5
D49: Mostrar contenido del informe en vista interna legible. | E49: Manuel Vidal | F49: 3 | G49: Terminado | H49: Al presionar el botón, aparezca una vista del informe técnico (no necesariamente PDF), con los datos guardados en la BD | I49: 45816 | J49: 45818 | K49: 45818 | L49: 45819 | M49: 3
...

Sheet BurnUp-Down INC 4
A1: Periodo de Sprint 1 | D1: 45961 | E1: 45968 | F1: =E1-D1 -> 7
A3: BurnUp
B4: 45961 | C4: 45962 | D4: 45963 | E4: 45964 | F4: 45965 | G4: 45966 | H4: 45967 | I4: 45968 | J4: 45969
B5: Día 1 | C5: Día 2 | D5: Día 3 | E5: Día 4 | F5: Día 5 | G5: Día 6 | H5: Día 7 | I5: Día 8 | J5: Día 9
A6: Esfuerzo Real Acumulado (HH) | B6: 0 | C6: ='Registro de HH INC4'!C11 -> 0 | D6: ='Registro de HH INC4'!D11 -> 1 | E6: ='Registro de HH INC4'!E11 -> 1.5 | F6: ='Registro de HH INC4'!F11 -> 2.5 | G6: ='Registro de HH INC4'!G11 -> 4 | H6: ='Registro de HH INC4'!H11 -> 4.5 | I6: ='Registro de HH INC4'!I11 -> 4.5 | J6: ='Registro de HH INC4'!J11 -> 4.5
A7: Esfuerzo Estimado Acumulado (HH) | B7: 0 | C7: =SUM('Aux Esfuerzo Estimado INC4 SPT5'!B3:B1000) -> 0.5 | D7: =SUM('Aux Esfuerzo Estimado INC4 SPT5'!C3:C1000)+C7 -> 1 | E7: =SUM('Aux Esfuerzo Estimado INC4 SPT5'!D3:D1000)+D7 -> 2.5 | F7: =SUM('Aux Esfuerzo Estimado INC4 SPT5'!E3:E1000)+E7 -> 3.5 | G7: =SUM('Aux Esfuerzo Estimado INC4 SPT5'!F3:F1000)+F7 -> 4 | H7: =SUM('Aux Esfuerzo Estimado INC4 SPT5'!G3:G1000)+G7 -> 4.5 | I7: =SUM('Aux Esfuerzo Estimado INC4 SPT5'!H3:H1000)+H7 -> 5.5 | J7: =SUM('Aux Esfuerzo Estimado INC4 SPT5'!I3:I1000)+I7 -> 5.5
A9: BurnDown
B10: 45961 | C10: 45962 | D10: 45963 | E10: 45964 | F10: 45965 | G10: 45966 | H10: 45967 | I10: 45968 | J10: 45969
B11: Día 1 | C11: Día 2 | D11: Día 3 | E11: Día 4 | F11: Día 5 | G11: Día 6 | H11: Día 7 | I11: Día 8 | J11: Día 9
A12: Esfuerzo Real Restante (HH) | B12: =SUM('ProductSprint Backlog'!M282:M289) -> 4.5 | C12: =B12-'Registro de HH INC4'!C10 -> 4.5 | D12: =C12-'Registro de HH INC4'!D10 -> 3.5 | E12: =D12-'Registro de HH INC4'!E10 -> 3 | F12: =E12-'Registro de HH INC4'!F10 -> 2 | G12: =F12-'Registro de HH INC4'!G10 -> 0.5 | H12: =G12-'Registro de HH INC4'!H10 -> 0 | I12: =H12-'Registro de HH INC4'!I10 -> 0 | J12: =I12-'Registro de HH INC4'!J10 -> 0
A13: Esfuerzo Estimado Restante (HH) | B13: =SUM('ProductSprint Backlog'!F282:F289) -> 5.5 | C13: =B13-SUM('Aux Esfuerzo Estimado INC4 SPT5'!B3:B1000) -> 5 | D13: =C13-SUM('Aux Esfuerzo Estimado INC4 SPT5'!C3:C1000) -> 4.5 | E13: =D13-SUM('Aux Esfuerzo Estimado INC4 SPT5'!D3:D1000) -> 3 | F13: =E13-SUM('Aux Esfuerzo Estimado INC4 SPT5'!E3:E1000) -> 2 | G13: =F13-SUM('Aux Esfuerzo Estimado INC4 SPT5'!F3:F1000) -> 1.5 | H13: =G13-SUM('Aux Esfuerzo Estimado INC4 SPT5'!G3:G1000) -> 1 | I13: =H13-SUM('Aux Esfuerzo Estimado INC4 SPT5'!H3:H1000) -> 0 | J13: =I13-SUM('Aux Esfuerzo Estimado INC4 SPT5'!I3:I1000) -> 0

Sheet Registro de HH INC4
A1: Sprint 2
B2: Dia 0 | C2: Dia 1 | D2: Dia 2 | E2: Dia 3 | F2: Dia 4 | G2: Dia 5 | H2: Dia 6 | I2: Dia 7 | J2: Dia 8 | K2: Dia 9
A3: Persona | C3: 45961 | D3: 45962 | E3: 45963 | F3: 45964 | G3: 45965 | H3: 45966 | I3: 45967 | J3: 45968 | K3: 45969
A4: Bastian | D4: 1 | E4: 0.5 | F4: 1 | G4: 1.5 | H4: 0.5
A5: Eliam
A6: Geronimo
A7: Manuel
A8: Samir
A9: Francisco
A10: Total Dia | C10: =SUM(C4:C9) -> 0 | D10: =SUM(D4:D9) -> 1 | E10: =SUM(E4:E9) -> 0.5 | F10: =SUM(F4:F9) -> 1 | G10: =SUM(G4:G9) -> 1.5 | H10: =SUM(H4:H9) -> 0.5 | I10: =SUM(I4:I9) -> 0 | J10: =SUM(J4:J9) -> 0 | K10: =SUM(K4:K9) -> 0
A11: Total Acumulado | C11: =SUM(C4:C9) -> 0 | D11: =SUM(D4:D9)+C11 -> 1 | E11: =SUM(E4:E9)+D11 -> 1.5 | F11: =SUM(F4:F9)+E11 -> 2.5 | G11: =SUM(G4:G9)+F11 -> 4 | H11: =SUM(H4:H9)+G11 -> 4.5 | I11: =SUM(I4:I9)+H11 -> 4.5 | J11: =SUM(J4:J9)+I11 -> 4.5 | K11: =SUM(K4:K9)+J11 -> 4.5

Sheet Tabla de Esfuerzo INC4 SPT5
B2: 45961 | C2: 45962 | D2: 45963 | E2: 45964 | F2: 45965 | G2: 45966 | H2: 45967 | I2: 45968
A3: Tareas Pendientes | B3: =COUNTIFS('ProductSprint Backlog'!$D$282:$D$289,"<>",'ProductSprint Backlog'!$L$282:$L$289,">"&DATEVALUE(B2)) -> 0 | C3: =COUNTIFS('ProductSprint Backlog'!$D$282:$D$289,"<>",'ProductSprint Backlog'!$L$282:$L$289,">"&DATEVALUE(C2)) -> 0 | D3: =COUNTIFS('ProductSprint Backlog'!$D$282:$D$289,"<>",'ProductSprint Backlog'!$L$282:$L$289,">"&DATEVALUE(D2)) -> 0 | E3: =COUNTIFS('ProductSprint Backlog'!$D$282:$D$289,"<>",'ProductSprint Backlog'!$L$282:$L$289,">"&DATEVALUE(E2)) -> 0 | F3: =COUNTIFS('ProductSprint Backlog'!$D$282:$D$289,"<>",'ProductSprint Backlog'!$L$282:$L$289,">"&DATEVALUE(F2)) -> 0 | G3: =COUNTIFS('ProductSprint Backlog'!$D$282:$D$289,"<>",'ProductSprint Backlog'!$L$282:$L$289,">"&DATEVALUE(G2)) -> 0 | H3: =COUNTIFS('ProductSprint Backlog'!$D$282:$D$289,"<>",'ProductSprint Backlog'!$L$282:$L$289,">"&DATEVALUE(H2)) -> 0 | I3: =COUNTIFS('ProductSprint Backlog'!$D$282:$D$289,"<>",'ProductSprint Backlog'!$L$282:$L$289,">"&DATEVALUE(I2)) -> 0
A6: Tarea | B6: Esfuerzo
A7: Diseñar botones e interfaces del proceso de eliminación | B7: =IF('ProductSprint Backlog'!$L282>B$2,'ProductSprint Backlog'!$M282,0) -> 0.5 | C7: =IF('ProductSprint Backlog'!$L282>C$2,'ProductSprint Backlog'!$M282,0) -> 0.5 | D7: =IF('ProductSprint Backlog'!$L282>D$2,'ProductSprint Backlog'!$M282,0) -> 0 | E7: =IF('ProductSprint Backlog'!$L282>E$2,'ProductSprint Backlog'!$M282,0) -> 0 | F7: =IF('ProductSprint Backlog'!$L282>F$2,'ProductSprint Backlog'!$M282,0) -> 0 | G7: =IF('ProductSprint Backlog'!$L282>G$2,'ProductSprint Backlog'!$M282,0) -> 0 | H7: =IF('ProductSprint Backlog'!$L282>H$2,'ProductSprint Backlog'!$M282,0) -> 0 | I7: =IF('ProductSprint Backlog'!$L282>I$2,'ProductSprint Backlog'!$M282,0) -> 0
A8: Mostrar el modal de confirmación, incluyendo el campo de detalles. | B8: =IF('ProductSprint Backlog'!$L283>B$2,'ProductSprint Backlog'!$M283,0) -> 0.5 | C8: =IF('ProductSprint Backlog'!$L283>C$2,'ProductSprint Backlog'!$M283,0) -> 0.5 | D8: =IF('ProductSprint Backlog'!$L283>D$2,'ProductSprint Backlog'!$M283,0) -> 0 | E8: =IF('ProductSprint Backlog'!$L283>E$2,'ProductSprint Backlog'!$M283,0) -> 0 | F8: =IF('ProductSprint Backlog'!$L283>F$2,'ProductSprint Backlog'!$M283,0) -> 0 | G8: =IF('ProductSprint Backlog'!$L283>G$2,'ProductSprint Backlog'!$M283,0) -> 0 | H8: =IF('ProductSprint Backlog'!$L283>H$2,'ProductSprint Backlog'!$M283,0) -> 0 | I8: =IF('ProductSprint Backlog'!$L283>I$2,'ProductSprint Backlog'!$M283,0) -> 0
A9: Asegurar el registro en auditoria para mantener la trazabilidad de las acciones | B9: =IF('ProductSprint Backlog'!$L284>B$2,'ProductSprint Backlog'!$M284,0) -> 1 | C9: =IF('ProductSprint Backlog'!$L284>C$2,'ProductSprint Backlog'!$M284,0) -> 1 | D9: =IF('ProductSprint Backlog'!$L284>D$2,'ProductSprint Backlog'!$M284,0) -> 1 | E9: =IF('ProductSprint Backlog'!$L284>E$2,'ProductSprint Backlog'!$M284,0) -> 0 | F9: =IF('ProductSprint Backlog'!$L284>F$2,'ProductSprint Backlog'!$M284,0) -> 0 | G9: =IF('ProductSprint Backlog'!$L284>G$2,'ProductSprint Backlog'!$M284,0) -> 0 | H9: =IF('ProductSprint Backlog'!$L284>H$2,'ProductSprint Backlog'!$M284,0) -> 0 | I9: =IF('ProductSprint Backlog'!$L284>I$2,'ProductSprint Backlog'!$M284,0) -> 0
A10: Diseñar y mostrar un mensaje de éxito al completar el proceso | B10: =IF('ProductSprint Backlog'!$L285>B$2,'ProductSprint Backlog'!$M285,0) -> 0.5 | C10: =IF('ProductSprint Backlog'!$L285>C$2,'ProductSprint Backlog'!$M285,0) -> 0.5 | D10: =IF('ProductSprint Backlog'!$L285>D$2,'ProductSprint Backlog'!$M285,0) -> 0.5 | E10: =IF('ProductSprint Backlog'!$L285>E$2,'ProductSprint Backlog'!$M285,0) -> 0.5 | F10: =IF('ProductSprint Backlog'!$L285>F$2,'ProductSprint Backlog'!$M285,0) -> 0 | G10: =IF('ProductSprint Backlog'!$L285>G$2,'ProductSprint Backlog'!$M285,0) -> 0 | H10: =IF('ProductSprint Backlog'!$L285>H$2,'ProductSprint Backlog'!$M285,0) -> 0 | I10: =IF('ProductSprint Backlog'!$L285>I$2,'ProductSprint Backlog'!$M285,0) -> 0
A11: Diseñar botones e interfaces del proceso de eliminación | B11: =IF('ProductSprint Backlog'!$L286>B$2,'ProductSprint Backlog'!$M286,0) -> 0.5 | C11: =IF('ProductSprint Backlog'!$L286>C$2,'ProductSprint Backlog'!$M286,0) -> 0.5 | D11: =IF('ProductSprint Backlog'!$L286>D$2,'ProductSprint Backlog'!$M286,0) -> 0.5 | E11: =IF('ProductSprint Backlog'!$L286>E$2,'ProductSprint Backlog'!$M286,0) -> 0.5 | F11: =IF('ProductSprint Backlog'!$L286>F$2,'ProductSprint Backlog'!$M286,0) -> 0 | G11: =IF('ProductSprint Backlog'!$L286>G$2,'ProductSprint Backlog'!$M286,0) -> 0 | H11: =IF('ProductSprint Backlog'!$L286>H$2,'ProductSprint Backlog'!$M286,0) -> 0 | I11: =IF('ProductSprint Backlog'!$L286>I$2,'ProductSprint Backlog'!$M286,0) -> 0
A12: Mostrar el modal de confirmación, incluyendo el campo de detalles. | B12: =IF('ProductSprint Backlog'!$L287>B$2,'ProductSprint Backlog'!$M287,0) -> 0.5 | C12: =IF('ProductSprint Backlog'!$L287>C$2,'ProductSprint Backlog'!$M287,0) -> 0.5 | D12: =IF('ProductSprint Backlog'!$L287>D$2,'ProductSprint Backlog'!$M287,0) -> 0.5 | E12: =IF('ProductSprint Backlog'!$L287>E$2,'ProductSprint Backlog'!$M287,0) -> 0.5 | F12: =IF('ProductSprint Backlog'!$L287>F$2,'ProductSprint Backlog'!$M287,0) -> 0.5 | G12: =IF('ProductSprint Backlog'!$L287>G$2,'ProductSprint Backlog'!$M287,0) -> 0 | H12: =IF('ProductSprint Backlog'!$L287>H$2,'ProductSprint Backlog'!$M287,0) -> 0 | I12: =IF('ProductSprint Backlog'!$L287>I$2,'ProductSprint Backlog'!$M287,0) -> 0
A13: Asegurar el registro en auditoria para mantener la trazabilidad de las acciones | B13: =IF('ProductSprint Backlog'!$L288>B$2,'ProductSprint Backlog'!$M288,0) -> 0.5 | C13: =IF('ProductSprint Backlog'!$L288>C$2,'ProductSprint Backlog'!$M288,0) -> 0.5 | D13: =IF('ProductSprint Backlog'!$L288>D$2,'ProductSprint Backlog'!$M288,0) -> 0.5 | E13: =IF('ProductSprint Backlog'!$L288>E$2,'ProductSprint Backlog'!$M288,0) -> 0.5 | F13: =IF('ProductSprint Backlog'!$L288>F$2,'ProductSprint Backlog'!$M288,0) -> 0.5 | G13: =IF('ProductSprint Backlog'!$L288>G$2,'ProductSprint Backlog'!$M288,0) -> 0 | H13: =IF('ProductSprint Backlog'!$L288>H$2,'ProductSprint Backlog'!$M288,0) -> 0 | I13: =IF('ProductSprint Backlog'!$L288>I$2,'ProductSprint Backlog'!$M288,0) -> 0
A14: Diseñar y mostrar un mensaje de éxito al completar el proceso | B14: =IF('ProductSprint Backlog'!$L289>B$2,'ProductSprint Backlog'!$M289,0) -> 0.5 | C14: =IF('ProductSprint Backlog'!$L289>C$2,'ProductSprint Backlog'!$M289,0) -> 0.5 | D14: =IF('ProductSprint Backlog'!$L289>D$2,'ProductSprint Backlog'!$M289,0) -> 0.5 | E14: =IF('ProductSprint Backlog'!$L289>E$2,'ProductSprint Backlog'!$M289,0) -> 0.5 | F14: =IF('ProductSprint Backlog'!$L289>F$2,'ProductSprint Backlog'!$M289,0) -> 0.5 | G14: =IF('ProductSprint Backlog'!$L289>G$2,'ProductSprint Backlog'!$M289,0) -> 0.5 | H14: =IF('ProductSprint Backlog'!$L289>H$2,'ProductSprint Backlog'!$M289,0) -> 0 | I14: =IF('ProductSprint Backlog'!$L289>I$2,'ProductSprint Backlog'!$M289,0) -> 0

Sheet Aux Esfuerzo Estimado INC4 SPT5
B1: Dia 1 | C1: Dia 2 | D1: Dia 3 | E1: Dia 4 | F1: Dia 5 | G1: Dia 6 | H1: Dia 7 | I1: Dia 8 | J1: Dia 9
B2: 45961 | C2: 45962 | D2: 45963 | E2: 45964 | F2: 45965 | G2: 45966 | H2: 45967 | I2: 45968 | J2: 45969 | R2: <------------------ | S2: Modificar esto para que calcular los esfuersos en el tiempo
B3: {=_xlfn.IFS('ProductSprint Backlog'!$F3="", "", AND('ProductSprint Backlog'!$J3>B$2,'ProductSprint Backlog'!$I3<=B$2), 'ProductSprint Backlog'!$F3 / MAX(1, 'ProductSprint Backlog'!$J3-'ProductSprint Backlog'!$I3), AND('ProductSprint Backlog'!$J3=B$2,'ProductSprint Backlog'!$I3=B$2), 'ProductSprint Backlog'!$F3, TRUE, 0)} -> 0 | C3: {=_xlfn.IFS('ProductSprint Backlog'!$F3="", "", AND('ProductSprint Backlog'!$J3>C$2,'ProductSprint Backlog'!$I3<=C$2), 'ProductSprint Backlog'!$F3 / MAX(1, 'ProductSprint Backlog'!$J3-'ProductSprint Backlog'!$I3), AND('ProductSprint Backlog'!$J3=C$2,'ProductSprint Backlog'!$I3=C$2), 'ProductSprint Backlog'!$F3, TRUE, 0)} -> 0 | D3: {=_xlfn.IFS('ProductSprint Backlog'!$F3="", "", AND('ProductSprint Backlog'!$J3>D$2,'ProductSprint Backlog'!$I3<=D$2), 'ProductSprint Backlog'!$F3 / MAX(1, 'ProductSprint Backlog'!$J3-'ProductSprint Backlog'!$I3), AND('ProductSprint Backlog'!$J3=D$2,'ProductSprint Backlog'!$I3=D$2), 'ProductSprint Backlog'!$F3, TRUE, 0)} -> 0 | E3: {=_xlfn.IFS('ProductSprint Backlog'!$F3="", "", AND('ProductSprint Backlog'!$J3>E$2,'ProductSprint Backlog'!$I3<=E$2), 'ProductSprint Backlog'!$F3 / MAX(1, 'ProductSprint Backlog'!$J3-'ProductSprint Backlog'!$I3), AND('ProductSprint Backlog'!$J3=E$2,'ProductSprint Backlog'!$I3=E$2), 'ProductSprint Backlog'!$F3, TRUE, 0)} -> 0 | F3: {=_xlfn.IFS('ProductSprint Backlog'!$F3="", "", AND('ProductSprint Backlog'!$J3>F$2,'ProductSprint Backlog'!$I3<=F$2), 'ProductSprint Backlog'!$F3 / MAX(1, 'ProductSprint Backlog'!$J3-'ProductSprint Backlog'!$I3), AND('ProductSprint Backlog'!$J3=F$2,'ProductSprint Backlog'!$I3=F$2), 'ProductSprint Backlog'!$F3, TRUE, 0)} -> 0 | G3: {=_xlfn.IFS('ProductSprint Backlog'!$F3="", "", AND('ProductSprint Backlog'!$J3>G$2,'ProductSprint Backlog'!$I3<=G$2), 'ProductSprint Backlog'!$F3 / MAX(1, 'ProductSprint Backlog'!$J3-'ProductSprint Backlog'!$I3), AND('ProductSprint Backlog'!$J3=G$2,'ProductSprint Backlog'!$I3=G$2), 'ProductSprint Backlog'!$F3, TRUE, 0)} -> 0 | H3: {=_xlfn.IFS('ProductSprint Backlog'!$F3="", "", AND('ProductSprint Backlog'!$J3>H$2,'ProductSprint Backlog'!$I3<=H$2), 'ProductSprint Backlog'!$F3 / MAX(1, 'ProductSprint Backlog'!$J3-'ProductSprint Backlog'!$I3), AND('ProductSprint Backlog'!$J3=H$2,'ProductSprint Backlog'!$I3=H$2), 'ProductSprint Backlog'!$F3, TRUE, 0)} -> 0 | I3: {=_xlfn.IFS('ProductSprint Backlog'!$F3="", "", AND('ProductSprint Backlog'!$J3>I$2,'ProductSprint Backlog'!$I3<=I$2), 'ProductSprint Backlog'!$F3 / MAX(1, 'ProductSprint Backlog'!$J3-'ProductSprint Backlog'!$I3), AND('ProductSprint Backlog'!$J3=I$2,'ProductSprint Backlog'!$I3=I$2), 'ProductSprint Backlog'!$F3, TRUE, 0)} -> 0 | J3: {=_xlfn.IFS('ProductSprint Backlog'!$F3="", "", AND('ProductSprint Backlog'!$J3>J$2,'ProductSprint Backlog'!$I3<=J$2), 'ProductSprint Backlog'!$F3 / MAX(1, 'ProductSprint Backlog'!$J3-'ProductSprint Backlog'!$I3), AND('ProductSprint Backlog'!$J3=J$2,'ProductSprint Backlog'!$I3=J$2), 'ProductSprint Backlog'!$F3, TRUE, 0)} -> 0
B4: {=_xlfn.IFS('ProductSprint Backlog'!$F4="", "", AND('ProductSprint Backlog'!$J4>B$2,'ProductSprint Backlog'!$I4<=B$2), 'ProductSprint Backlog'!$F4 / MAX(1, 'ProductSprint Backlog'!$J4-'ProductSprint Backlog'!$I4), AND('ProductSprint Backlog'!$J4=B$2,'ProductSprint Backlog'!$I4=B$2), 'ProductSprint Backlog'!$F4, TRUE, 0)} -> 0 | C4: {=_xlfn.IFS('ProductSprint Backlog'!$F4="", "", AND('ProductSprint Backlog'!$J4>C$2,'ProductSprint Backlog'!$I4<=C$2), 'ProductSprint Backlog'!$F4 / MAX(1, 'ProductSprint Backlog'!$J4-'ProductSprint Backlog'!$I4), AND('ProductSprint Backlog'!$J4=C$2,'ProductSprint Backlog'!$I4=C$2), 'ProductSprint Backlog'!$F4, TRUE, 0)} -> 0 | D4: {=_xlfn.IFS('ProductSprint Backlog'!$F4="", "", AND('ProductSprint Backlog'!$J4>D$2,'ProductSprint Backlog'!$I4<=D$2), 'ProductSprint Backlog'!$F4 / MAX(1, 'ProductSprint Backlog'!$J4-'ProductSprint Backlog'!$I4), AND('ProductSprint Backlog'!$J4=D$2,'ProductSprint Backlog'!$I4=D$2), 'ProductSprint Backlog'!$F4, TRUE, 0)} -> 0 | E4: {=_xlfn.IFS('ProductSprint Backlog'!$F4="", "", AND('ProductSprint Backlog'!$J4>E$2,'ProductSprint Backlog'!$I4<=E$2), 'ProductSprint Backlog'!$F4 / MAX(1, 'ProductSprint Backlog'!$J4-'ProductSprint Backlog'!$I4), AND('ProductSprint Backlog'!$J4=E$2,'ProductSprint Backlog'!$I4=E$2), 'ProductSprint Backlog'!$F4, TRUE, 0)} -> 0 | F4: {=_xlfn.IFS('ProductSprint Backlog'!$F4="", "", AND('ProductSprint Backlog'!$J4>F$2,'ProductSprint Backlog'!$I4<=F$2), 'ProductSprint Backlog'!$F4 / MAX(1, 'ProductSprint Backlog'!$J4-'ProductSprint Backlog'!$I4), AND('ProductSprint Backlog'!$J4=F$2,'ProductSprint Backlog'!$I4=F$2), 'ProductSprint Backlog'!$F4, TRUE, 0)} -> 0 | G4: {=_xlfn.IFS('ProductSprint Backlog'!$F4="", "", AND('ProductSprint Backlog'!$J4>G$2,'ProductSprint Backlog'!$I4<=G$2), 'ProductSprint Backlog'!$F4 / MAX(1, 'ProductSprint Backlog'!$J4-'ProductSprint Backlog'!$I4), AND('ProductSprint Backlog'!$J4=G$2,'ProductSprint Backlog'!$I4=G$2), 'ProductSprint Backlog'!$F4, TRUE, 0)} -> 0 | H4: {=_xlfn.IFS('ProductSprint Backlog'!$F4="", "", AND('ProductSprint Backlog'!$J4>H$2,'ProductSprint Backlog'!$I4<=H$2), 'ProductSprint Backlog'!$F4 / MAX(1, 'ProductSprint Backlog'!$J4-'ProductSprint Backlog'!$I4), AND('ProductSprint Backlog'!$J4=H$2,'ProductSprint Backlog'!$I4=H$2), 'ProductSprint Backlog'!$F4, TRUE, 0)} -> 0 | I4: {=_xlfn.IFS('ProductSprint Backlog'!$F4="", "", AND('ProductSprint Backlog'!$J4>I$2,'ProductSprint Backlog'!$I4<=I$2), 'ProductSprint Backlog'!$F4 / MAX(1, 'ProductSprint Backlog'!$J4-'ProductSprint Backlog'!$I4), AND('ProductSprint Backlog'!$J4=I$2,'ProductSprint Backlog'!$I4=I$2), 'ProductSprint Backlog'!$F4, TRUE, 0)} -> 0 | J4: {=_xlfn.IFS('ProductSprint Backlog'!$F4="", "", AND('ProductSprint Backlog'!$J4>J$2,'ProductSprint Backlog'!$I4<=J$2), 'ProductSprint Backlog'!$F4 / MAX(1, 'ProductSprint Backlog'!$J4-'ProductSprint Backlog'!$I4), AND('ProductSprint Backlog'!$J4=J$2,'ProductSprint Backlog'!$I4=J$2), 'ProductSprint Backlog'!$F4, TRUE, 0)} -> 0
B5: {=_xlfn.IFS('ProductSprint Backlog'!$F5="", "", AND('ProductSprint Backlog'!$J5>B$2,'ProductSprint Backlog'!$I5<=B$2), 'ProductSprint Backlog'!$F5 / MAX(1, 'ProductSprint Backlog'!$J5-'ProductSprint Backlog'!$I5), AND('ProductSprint Backlog'!$J5=B$2,'ProductSprint Backlog'!$I5=B$2), 'ProductSprint Backlog'!$F5, TRUE, 0)} -> 0 | C5: {=_xlfn.IFS('ProductSprint Backlog'!$F5="", "", AND('ProductSprint Backlog'!$J5>C$2,'ProductSprint Backlog'!$I5<=C$2), 'ProductSprint Backlog'!$F5 / MAX(1, 'ProductSprint Backlog'!$J5-'ProductSprint Backlog'!$I5), AND('ProductSprint Backlog'!$J5=C$2,'ProductSprint Backlog'!$I5=C$2), 'ProductSprint Backlog'!$F5, TRUE, 0)} -> 0 | D5: {=_xlfn.IFS('ProductSprint Backlog'!$F5="", "", AND('ProductSprint Backlog'!$J5>D$2,'ProductSprint Backlog'!$I5<=D$2), 'ProductSprint Backlog'!$F5 / MAX(1, 'ProductSprint Backlog'!$J5-'ProductSprint Backlog'!$I5), AND('ProductSprint Backlog'!$J5=D$2,'ProductSprint Backlog'!$I5=D$2), 'ProductSprint Backlog'!$F5, TRUE, 0)} -> 0 | E5: {=_xlfn.IFS('ProductSprint Backlog'!$F5="", "", AND('ProductSprint Backlog'!$J5>E$2,'ProductSprint Backlog'!$I5<=E$2), 'ProductSprint Backlog'!$F5 / MAX(1, 'ProductSprint Backlog'!$J5-'ProductSprint Backlog'!$I5), AND('ProductSprint Backlog'!$J5=E$2,'ProductSprint Backlog'!$I5=E$2), 'ProductSprint Backlog'!$F5, TRUE, 0)} -> 0 | F5: {=_xlfn.IFS('ProductSprint Backlog'!$F5="", "", AND('ProductSprint Backlog'!$J5>F$2,'ProductSprint Backlog'!$I5<=F$2), 'ProductSprint Backlog'!$F5 / MAX(1, 'ProductSprint Backlog'!$J5-'ProductSprint Backlog'!$I5), AND('ProductSprint Backlog'!$J5=F$2,'ProductSprint Backlog'!$I5=F$2), 'ProductSprint Backlog'!$F5, TRUE, 0)} -> 0 | G5: {=_xlfn.IFS('ProductSprint Backlog'!$F5="", "", AND('ProductSprint Backlog'!$J5>G$2,'ProductSprint Backlog'!$I5<=G$2), 'ProductSprint Backlog'!$F5 / MAX(1, 'ProductSprint Backlog'!$J5-'ProductSprint Backlog'!$I5), AND('ProductSprint Backlog'!$J5=G$2,'ProductSprint Backlog'!$I5=G$2), 'ProductSprint Backlog'!$F5, TRUE, 0)} -> 0 | H5: {=_xlfn.IFS('ProductSprint Backlog'!$F5="", "", AND('ProductSprint Backlog'!$J5>H$2,'ProductSprint Backlog'!$I5<=H$2), 'ProductSprint Backlog'!$F5 / MAX(1, 'ProductSprint Backlog'!$J5-'ProductSprint Backlog'!$I5), AND('ProductSprint Backlog'!$J5=H$2,'ProductSprint Backlog'!$I5=H$2), 'ProductSprint Backlog'!$F5, TRUE, 0)} -> 0 | I5: {=_xlfn.IFS('ProductSprint Backlog'!$F5="", "", AND('ProductSprint Backlog'!$J5>I$2,'ProductSprint Backlog'!$I5<=I$2), 'ProductSprint Backlog'!$F5 / MAX(1, 'ProductSprint Backlog'!$J5-'ProductSprint Backlog'!$I5), AND('ProductSprint Backlog'!$J5=I$2,'ProductSprint Backlog'!$I5=I$2), 'ProductSprint Backlog'!$F5, TRUE, 0)} -> 0 | J5: {=_xlfn.IFS('ProductSprint Backlog'!$F5="", "", AND('ProductSprint Backlog'!$J5>J$2,'ProductSprint Backlog'!$I5<=J$2), 'ProductSprint Backlog'!$F5 / MAX(1, 'ProductSprint Backlog'!$J5-'ProductSprint Backlog'!$I5), AND('ProductSprint Backlog'!$J5=J$2,'ProductSprint Backlog'!$I5=J$2), 'ProductSprint Backlog'!$F5, TRUE, 0)} -> 0
B6: {=_xlfn.IFS('ProductSprint Backlog'!$F6="", "", AND('ProductSprint Backlog'!$J6>B$2,'ProductSprint Backlog'!$I6<=B$2), 'ProductSprint Backlog'!$F6 / MAX(1, 'ProductSprint Backlog'!$J6-'ProductSprint Backlog'!$I6), AND('ProductSprint Backlog'!$J6=B$2,'ProductSprint Backlog'!$I6=B$2), 'ProductSprint Backlog'!$F6, TRUE, 0)} -> 0 | C6: {=_xlfn.IFS('ProductSprint Backlog'!$F6="", "", AND('ProductSprint Backlog'!$J6>C$2,'ProductSprint Backlog'!$I6<=C$2), 'ProductSprint Backlog'!$F6 / MAX(1, 'ProductSprint Backlog'!$J6-'ProductSprint Backlog'!$I6), AND('ProductSprint Backlog'!$J6=C$2,'ProductSprint Backlog'!$I6=C$2), 'ProductSprint Backlog'!$F6, TRUE, 0)} -> 0 | D6: {=_xlfn.IFS('ProductSprint Backlog'!$F6="", "", AND('ProductSprint Backlog'!$J6>D$2,'ProductSprint Backlog'!$I6<=D$2), 'ProductSprint Backlog'!$F6 / MAX(1, 'ProductSprint Backlog'!$J6-'ProductSprint Backlog'!$I6), AND('ProductSprint Backlog'!$J6=D$2,'ProductSprint Backlog'!$I6=D$2), 'ProductSprint Backlog'!$F6, TRUE, 0)} -> 0 | E6: {=_xlfn.IFS('ProductSprint Backlog'!$F6="", "", AND('ProductSprint Backlog'!$J6>E$2,'ProductSprint Backlog'!$I6<=E$2), 'ProductSprint Backlog'!$F6 / MAX(1, 'ProductSprint Backlog'!$J6-'ProductSprint Backlog'!$I6), AND('ProductSprint Backlog'!$J6=E$2,'ProductSprint Backlog'!$I6=E$2), 'ProductSprint Backlog'!$F6, TRUE, 0)} -> 0 | F6: {=_xlfn.IFS('ProductSprint Backlog'!$F6="", "", AND('ProductSprint Backlog'!$J6>F$2,'ProductSprint Backlog'!$I6<=F$2), 'ProductSprint Backlog'!$F6 / MAX(1, 'ProductSprint Backlog'!$J6-'ProductSprint Backlog'!$I6), AND('ProductSprint Backlog'!$J6=F$2,'ProductSprint Backlog'!$I6=F$2), 'ProductSprint Backlog'!$F6, TRUE, 0)} -> 0 | G6: {=_xlfn.IFS('ProductSprint Backlog'!$F6="", "", AND('ProductSprint Backlog'!$J6>G$2,'ProductSprint Backlog'!$I6<=G$2), 'ProductSprint Backlog'!$F6 / MAX(1, 'ProductSprint Backlog'!$J6-'ProductSprint Backlog'!$I6), AND('ProductSprint Backlog'!$J6=G$2,'ProductSprint Backlog'!$I6=G$2), 'ProductSprint Backlog'!$F6, TRUE, 0)} -> 0 | H6: {=_xlfn.IFS('ProductSprint Backlog'!$F6="", "", AND('ProductSprint Backlog'!$J6>H$2,'ProductSprint Backlog'!$I6<=H$2), 'ProductSprint Backlog'!$F6 / MAX(1, 'ProductSprint Backlog'!$J6-'ProductSprint Backlog'!$I6), AND('ProductSprint Backlog'!$J6=H$2,'ProductSprint Backlog'!$I6=H$2), 'ProductSprint Backlog'!$F6, TRUE, 0)} -> 0 | I6: {=_xlfn.IFS('ProductSprint Backlog'!$F6="", "", AND('ProductSprint Backlog'!$J6>I$2,'ProductSprint Backlog'!$I6<=I$2), 'ProductSprint Backlog'!$F6 / MAX(1, 'ProductSprint Backlog'!$J6-'ProductSprint Backlog'!$I6), AND('ProductSprint Backlog'!$J6=I$2,'ProductSprint Backlog'!$I6=I$2), 'ProductSprint Backlog'!$F6, TRUE, 0)} -> 0 | J6: {=_xlfn.IFS('ProductSprint Backlog'!$F6="", "", AND('ProductSprint Backlog'!$J6>J$2,'ProductSprint Backlog'!$I6<=J$2), 'ProductSprint Backlog'!$F6 / MAX(1, 'ProductSprint Backlog'!$J6-'ProductSprint Backlog'!$I6), AND('ProductSprint Backlog'!$J6=J$2,'ProductSprint Backlog'!$I6=J$2), 'ProductSprint Backlog'!$F6, TRUE, 0)} -> 0
B7: {=_xlfn.IFS('ProductSprint Backlog'!$F7="", "", AND('ProductSprint Backlog'!$J7>B$2,'ProductSprint Backlog'!$I7<=B$2), 'ProductSprint Backlog'!$F7 / MAX(1, 'ProductSprint Backlog'!$J7-'ProductSprint Backlog'!$I7), AND('ProductSprint Backlog'!$J7=B$2,'ProductSprint Backlog'!$I7=B$2), 'ProductSprint Backlog'!$F7, TRUE, 0)} | C7: {=_xlfn.IFS('ProductSprint Backlog'!$F7="", "", AND('ProductSprint Backlog'!$J7>C$2,'ProductSprint Backlog'!$I7<=C$2), 'ProductSprint Backlog'!$F7 / MAX(1, 'ProductSprint Backlog'!$J7-'ProductSprint Backlog'!$I7), AND('ProductSprint Backlog'!$J7=C$2,'ProductSprint Backlog'!$I7=C$2), 'ProductSprint Backlog'!$F7, TRUE, 0)} | D7: {=_xlfn.IFS('ProductSprint Backlog'!$F7="", "", AND('ProductSprint Backlog'!$J7>D$2,'ProductSprint Backlog'!$I7<=D$2), 'ProductSprint Backlog'!$F7 / MAX(1, 'ProductSprint Backlog'!$J7-'ProductSprint Backlog'!$I7), AND('ProductSprint Backlog'!$J7=D$2,'ProductSprint Backlog'!$I7=D$2), 'ProductSprint Backlog'!$F7, TRUE, 0)} | E7: {=_xlfn.IFS('ProductSprint Backlog'!$F7="", "", AND('ProductSprint Backlog'!$J7>E$2,'ProductSprint Backlog'!$I7<=E$2), 'ProductSprint Backlog'!$F7 / MAX(1, 'ProductSprint Backlog'!$J7-'ProductSprint Backlog'!$I7), AND('ProductSprint Backlog'!$J7=E$2,'ProductSprint Backlog'!$I7=E$2), 'ProductSprint Backlog'!$F7, TRUE, 0)} | F7: {=_xlfn.IFS('ProductSprint Backlog'!$F7="", "", AND('ProductSprint Backlog'!$J7>F$2,'ProductSprint Backlog'!$I7<=F$2), 'ProductSprint Backlog'!$F7 / MAX(1, 'ProductSprint Backlog'!$J7-'ProductSprint Backlog'!$I7), AND('ProductSprint Backlog'!$J7=F$2,'ProductSprint Backlog'!$I7=F$2), 'ProductSprint Backlog'!$F7, TRUE, 0)} | G7: {=_xlfn.IFS('ProductSprint Backlog'!$F7="", "", AND('ProductSprint Backlog'!$J7>G$2,'ProductSprint Backlog'!$I7<=G$2), 'ProductSprint Backlog'!$F7 / MAX(1, 'ProductSprint Backlog'!$J7-'ProductSprint Backlog'!$I7), AND('ProductSprint Backlog'!$J7=G$2,'ProductSprint Backlog'!$I7=G$2), 'ProductSprint Backlog'!$F7, TRUE, 0)} | H7: {=_xlfn.IFS('ProductSprint Backlog'!$F7="", "", AND('ProductSprint Backlog'!$J7>H$2,'ProductSprint Backlog'!$I7<=H$2), 'ProductSprint Backlog'!$F7 / MAX(1, 'ProductSprint Backlog'!$J7-'ProductSprint Backlog'!$I7), AND('ProductSprint Backlog'!$J7=H$2,'ProductSprint Backlog'!$I7=H$2), 'ProductSprint Backlog'!$F7, TRUE, 0)} | I7: {=_xlfn.IFS('ProductSprint Backlog'!$F7="", "", AND('ProductSprint Backlog'!$J7>I$2,'ProductSprint Backlog'!$I7<=I$2), 'ProductSprint Backlog'!$F7 / MAX(1, 'ProductSprint Backlog'!$J7-'ProductSprint Backlog'!$I7), AND('ProductSprint Backlog'!$J7=I$2,'ProductSprint Backlog'!$I7=I$2), 'ProductSprint Backlog'!$F7, TRUE, 0)} | J7: {=_xlfn.IFS('ProductSprint Backlog'!$F7="", "", AND('ProductSprint Backlog'!$J7>J$2,'ProductSprint Backlog'!$I7<=J$2), 'ProductSprint Backlog'!$F7 / MAX(1, 'ProductSprint Backlog'!$J7-'ProductSprint Backlog'!$I7), AND('ProductSprint Backlog'!$J7=J$2,'ProductSprint Backlog'!$I7=J$2), 'ProductSprint Backlog'!$F7, TRUE, 0)}
B8: {=_xlfn.IFS('ProductSprint Backlog'!$F8="", "", AND('ProductSprint Backlog'!$J8>B$2,'ProductSprint Backlog'!$I8<=B$2), 'ProductSprint Backlog'!$F8 / MAX(1, 'ProductSprint Backlog'!$J8-'ProductSprint Backlog'!$I8), AND('ProductSprint Backlog'!$J8=B$2,'ProductSprint Backlog'!$I8=B$2), 'ProductSprint Backlog'!$F8, TRUE, 0)} -> 0 | C8: {=_xlfn.IFS('ProductSprint Backlog'!$F8="", "", AND('ProductSprint Backlog'!$J8>C$2,'ProductSprint Backlog'!$I8<=C$2), 'ProductSprint Backlog'!$F8 / MAX(1, 'ProductSprint Backlog'!$J8-'ProductSprint Backlog'!$I8), AND('ProductSprint Backlog'!$J8=C$2,'ProductSprint Backlog'!$I8=C$2), 'ProductSprint Backlog'!$F8, TRUE, 0)} -> 0 | D8: {=_xlfn.IFS('ProductSprint Backlog'!$F8="", "", AND('ProductSprint Backlog'!$J8>D$2,'ProductSprint Backlog'!$I8<=D$2), 'ProductSprint Backlog'!$F8 / MAX(1, 'ProductSprint Backlog'!$J8-'ProductSprint Backlog'!$I8), AND('ProductSprint Backlog'!$J8=D$2,'ProductSprint Backlog'!$I8=D$2), 'ProductSprint Backlog'!$F8, TRUE, 0)} -> 0 | E8: {=_xlfn.IFS('ProductSprint Backlog'!$F8="", "", AND('ProductSprint Backlog'!$J8>E$2,'ProductSprint Backlog'!$I8<=E$2), 'ProductSprint Backlog'!$F8 / MAX(1, 'ProductSprint Backlog'!$J8-'ProductSprint Backlog'!$I8), AND('ProductSprint Backlog'!$J8=E$2,'ProductSprint Backlog'!$I8=E$2), 'ProductSprint Backlog'!$F8, TRUE, 0)} -> 0 | F8: {=_xlfn.IFS('ProductSprint Backlog'!$F8="", "", AND('ProductSprint Backlog'!$J8>F$2,'ProductSprint Backlog'!$I8<=F$2), 'ProductSprint Backlog'!$F8 / MAX(1, 'ProductSprint Backlog'!$J8-'ProductSprint Backlog'!$I8), AND('ProductSprint Backlog'!$J8=F$2,'ProductSprint Backlog'!$I8=F$2), 'ProductSprint Backlog'!$F8, TRUE, 0)} -> 0 | G8: {=_xlfn.IFS('ProductSprint Backlog'!$F8="", "", AND('ProductSprint Backlog'!$J8>G$2,'ProductSprint Backlog'!$I8<=G$2), 'ProductSprint Backlog'!$F8 / MAX(1, 'ProductSprint Backlog'!$J8-'ProductSprint Backlog'!$I8), AND('ProductSprint Backlog'!$J8=G$2,'ProductSprint Backlog'!$I8=G$2), 'ProductSprint Backlog'!$F8, TRUE, 0)} -> 0 | H8: {=_xlfn.IFS('ProductSprint Backlog'!$F8="", "", AND('ProductSprint Backlog'!$J8>H$2,'ProductSprint Backlog'!$I8<=H$2), 'ProductSprint Backlog'!$F8 / MAX(1, 'ProductSprint Backlog'!$J8-'ProductSprint Backlog'!$I8), AND('ProductSprint Backlog'!$J8=H$2,'ProductSprint Backlog'!$I8=H$2), 'ProductSprint Backlog'!$F8, TRUE, 0)} -> 0 | I8: {=_xlfn.IFS('ProductSprint Backlog'!$F8="", "", AND('ProductSprint Backlog'!$J8>I$2,'ProductSprint Backlog'!$I8<=I$2), 'ProductSprint Backlog'!$F8 / MAX(1, 'ProductSprint Backlog'!$J8-'ProductSprint Backlog'!$I8), AND('ProductSprint Backlog'!$J8=I$2,'ProductSprint Backlog'!$I8=I$2), 'ProductSprint Backlog'!$F8, TRUE, 0)} -> 0 | J8: {=_xlfn.IFS('ProductSprint Backlog'!$F8="", "", AND('ProductSprint Backlog'!$J8>J$2,'ProductSprint Backlog'!$I8<=J$2), 'ProductSprint Backlog'!$F8 / MAX(1, 'ProductSprint Backlog'!$J8-'ProductSprint Backlog'!$I8), AND('ProductSprint Backlog'!$J8=J$2,'ProductSprint Backlog'!$I8=J$2), 'ProductSprint Backlog'!$F8, TRUE, 0)} -> 0
B9: {=_xlfn.IFS('ProductSprint Backlog'!$F9="", "", AND('ProductSprint Backlog'!$J9>B$2,'ProductSprint Backlog'!$I9<=B$2), 'ProductSprint Backlog'!$F9 / MAX(1, 'ProductSprint Backlog'!$J9-'ProductSprint Backlog'!$I9), AND('ProductSprint Backlog'!$J9=B$2,'ProductSprint Backlog'!$I9=B$2), 'ProductSprint Backlog'!$F9, TRUE, 0)} -> 0 | C9: {=_xlfn.IFS('ProductSprint Backlog'!$F9="", "", AND('ProductSprint Backlog'!$J9>C$2,'ProductSprint Backlog'!$I9<=C$2), 'ProductSprint Backlog'!$F9 / MAX(1, 'ProductSprint Backlog'!$J9-'ProductSprint Backlog'!$I9), AND('ProductSprint Backlog'!$J9=C$2,'ProductSprint Backlog'!$I9=C$2), 'ProductSprint Backlog'!$F9, TRUE, 0)} -> 0 | D9: {=_xlfn.IFS('ProductSprint Backlog'!$F9="", "", AND('ProductSprint Backlog'!$J9>D$2,'ProductSprint Backlog'!$I9<=D$2), 'ProductSprint Backlog'!$F9 / MAX(1, 'ProductSprint Backlog'!$J9-'ProductSprint Backlog'!$I9), AND('ProductSprint Backlog'!$J9=D$2,'ProductSprint Backlog'!$I9=D$2), 'ProductSprint Backlog'!$F9, TRUE, 0)} -> 0 | E9: {=_xlfn.IFS('ProductSprint Backlog'!$F9="", "", AND('ProductSprint Backlog'!$J9>E$2,'ProductSprint Backlog'!$I9<=E$2), 'ProductSprint Backlog'!$F9 / MAX(1, 'ProductSprint Backlog'!$J9-'ProductSprint Backlog'!$I9), AND('ProductSprint Backlog'!$J9=E$2,'ProductSprint Backlog'!$I9=E$2), 'ProductSprint Backlog'!$F9, TRUE, 0)} -> 0 | F9: {=_xlfn.IFS('ProductSprint Backlog'!$F9="", "", AND('ProductSprint Backlog'!$J9>F$2,'ProductSprint Backlog'!$I9<=F$2), 'ProductSprint Backlog'!$F9 / MAX(1, 'ProductSprint Backlog'!$J9-'ProductSprint Backlog'!$I9), AND('ProductSprint Backlog'!$J9=F$2,'ProductSprint Backlog'!$I9=F$2), 'ProductSprint Backlog'!$F9, TRUE, 0)} -> 0 | G9: {=_xlfn.IFS('ProductSprint Backlog'!$F9="", "", AND('ProductSprint Backlog'!$J9>G$2,'ProductSprint Backlog'!$I9<=G$2), 'ProductSprint Backlog'!$F9 / MAX(1, 'ProductSprint Backlog'!$J9-'ProductSprint Backlog'!$I9), AND('ProductSprint Backlog'!$J9=G$2,'ProductSprint Backlog'!$I9=G$2), 'ProductSprint Backlog'!$F9, TRUE, 0)} -> 0 | H9: {=_xlfn.IFS('ProductSprint Backlog'!$F9="", "", AND('ProductSprint Backlog'!$J9>H$2,'ProductSprint Backlog'!$I9<=H$2), 'ProductSprint Backlog'!$F9 / MAX(1, 'ProductSprint Backlog'!$J9-'ProductSprint Backlog'!$I9), AND('ProductSprint Backlog'!$J9=H$2,'ProductSprint Backlog'!$I9=H$2), 'ProductSprint Backlog'!$F9, TRUE, 0)} -> 0 | I9: {=_xlfn.IFS('ProductSprint Backlog'!$F9="", "", AND('ProductSprint Backlog'!$J9>I$2,'ProductSprint Backlog'!$I9<=I$2), 'ProductSprint Backlog'!$F9 / MAX(1, 'ProductSprint Backlog'!$J9-'ProductSprint Backlog'!$I9), AND('ProductSprint Backlog'!$J9=I$2,'ProductSprint Backlog'!$I9=I$2), 'ProductSprint Backlog'!$F9, TRUE, 0)} -> 0 | J9: {=_xlfn.IFS('ProductSprint Backlog'!$F9="", "", AND('ProductSprint Backlog'!$J9>J$2,'ProductSprint Backlog'!$I9<=J$2), 'ProductSprint Backlog'!$F9 / MAX(1, 'ProductSprint Backlog'!$J9-'ProductSprint Backlog'!$I9), AND('ProductSprint Backlog'!$J9=J$2,'ProductSprint Backlog'!$I9=J$2), 'ProductSprint Backlog'!$F9, TRUE, 0)} -> 0
B10: {=_xlfn.IFS('ProductSprint Backlog'!$F10="", "", AND('ProductSprint Backlog'!$J10>B$2,'ProductSprint Backlog'!$I10<=B$2), 'ProductSprint Backlog'!$F10 / MAX(1, 'ProductSprint Backlog'!$J10-'ProductSprint Backlog'!$I10), AND('ProductSprint Backlog'!$J10=B$2,'ProductSprint Backlog'!$I10=B$2), 'ProductSprint Backlog'!$F10, TRUE, 0)} -> 0 | C10: {=_xlfn.IFS('ProductSprint Backlog'!$F10="", "", AND('ProductSprint Backlog'!$J10>C$2,'ProductSprint Backlog'!$I10<=C$2), 'ProductSprint Backlog'!$F10 / MAX(1, 'ProductSprint Backlog'!$J10-'ProductSprint Backlog'!$I10), AND('ProductSprint Backlog'!$J10=C$2,'ProductSprint Backlog'!$I10=C$2), 'ProductSprint Backlog'!$F10, TRUE, 0)} -> 0 | D10: {=_xlfn.IFS('ProductSprint Backlog'!$F10="", "", AND('ProductSprint Backlog'!$J10>D$2,'ProductSprint Backlog'!$I10<=D$2), 'ProductSprint Backlog'!$F10 / MAX(1, 'ProductSprint Backlog'!$J10-'ProductSprint Backlog'!$I10), AND('ProductSprint Backlog'!$J10=D$2,'ProductSprint Backlog'!$I10=D$2), 'ProductSprint Backlog'!$F10, TRUE, 0)} -> 0 | E10: {=_xlfn.IFS('ProductSprint Backlog'!$F10="", "", AND('ProductSprint Backlog'!$J10>E$2,'ProductSprint Backlog'!$I10<=E$2), 'ProductSprint Backlog'!$F10 / MAX(1, 'ProductSprint Backlog'!$J10-'ProductSprint Backlog'!$I10), AND('ProductSprint Backlog'!$J10=E$2,'ProductSprint Backlog'!$I10=E$2), 'ProductSprint Backlog'!$F10, TRUE, 0)} -> 0 | F10: {=_xlfn.IFS('ProductSprint Backlog'!$F10="", "", AND('ProductSprint Backlog'!$J10>F$2,'ProductSprint Backlog'!$I10<=F$2), 'ProductSprint Backlog'!$F10 / MAX(1, 'ProductSprint Backlog'!$J10-'ProductSprint Backlog'!$I10), AND('ProductSprint Backlog'!$J10=F$2,'ProductSprint Backlog'!$I10=F$2), 'ProductSprint Backlog'!$F10, TRUE, 0)} -> 0 | G10: {=_xlfn.IFS('ProductSprint Backlog'!$F10="", "", AND('ProductSprint Backlog'!$J10>G$2,'ProductSprint Backlog'!$I10<=G$2), 'ProductSprint Backlog'!$F10 / MAX(1, 'ProductSprint Backlog'!$J10-'ProductSprint Backlog'!$I10), AND('ProductSprint Backlog'!$J10=G$2,'ProductSprint Backlog'!$I10=G$2), 'ProductSprint Backlog'!$F10, TRUE, 0)} -> 0 | H10: {=_xlfn.IFS('ProductSprint Backlog'!$F10="", "", AND('ProductSprint Backlog'!$J10>H$2,'ProductSprint Backlog'!$I10<=H$2), 'ProductSprint Backlog'!$F10 / MAX(1, 'ProductSprint Backlog'!$J10-'ProductSprint Backlog'!$I10), AND('ProductSprint Backlog'!$J10=H$2,'ProductSprint Backlog'!$I10=H$2), 'ProductSprint Backlog'!$F10, TRUE, 0)} -> 0 | I10: {=_xlfn.IFS('ProductSprint Backlog'!$F10="", "", AND('ProductSprint Backlog'!$J10>I$2,'ProductSprint Backlog'!$I10<=I$2), 'ProductSprint Backlog'!$F10 / MAX(1, 'ProductSprint Backlog'!$J10-'ProductSprint Backlog'!$I10), AND('ProductSprint Backlog'!$J10=I$2,'ProductSprint Backlog'!$I10=I$2), 'ProductSprint Backlog'!$F10, TRUE, 0)} -> 0 | J10: {=_xlfn.IFS('ProductSprint Backlog'!$F10="", "", AND('ProductSprint Backlog'!$J10>J$2,'ProductSprint Backlog'!$I10<=J$2), 'ProductSprint Backlog'!$F10 / MAX(1, 'ProductSprint Backlog'!$J10-'ProductSprint Backlog'!$I10), AND('ProductSprint Backlog'!$J10=J$2,'ProductSprint Backlog'!$I10=J$2), 'ProductSprint Backlog'!$F10, TRUE, 0)} -> 0
B11: {=_xlfn.IFS('ProductSprint Backlog'!$F11="", "", AND('ProductSprint Backlog'!$J11>B$2,'ProductSprint Backlog'!$I11<=B$2), 'ProductSprint Backlog'!$F11 / MAX(1, 'ProductSprint Backlog'!$J11-'ProductSprint Backlog'!$I11), AND('ProductSprint Backlog'!$J11=B$2,'ProductSprint Backlog'!$I11=B$2), 'ProductSprint Backlog'!$F11, TRUE, 0)} -> 0 | C11: {=_xlfn.IFS('ProductSprint Backlog'!$F11="", "", AND('ProductSprint Backlog'!$J11>C$2,'ProductSprint Backlog'!$I11<=C$2), 'ProductSprint Backlog'!$F11 / MAX(1, 'ProductSprint Backlog'!$J11-'ProductSprint Backlog'!$I11), AND('ProductSprint Backlog'!$J11=C$2,'ProductSprint Backlog'!$I11=C$2), 'ProductSprint Backlog'!$F11, TRUE, 0)} -> 0 | D11: {=_xlfn.IFS('ProductSprint Backlog'!$F11="", "", AND('ProductSprint Backlog'!$J11>D$2,'ProductSprint Backlog'!$I11<=D$2), 'ProductSprint Backlog'!$F11 / MAX(1, 'ProductSprint Backlog'!$J11-'ProductSprint Backlog'!$I11), AND('ProductSprint Backlog'!$J11=D$2,'ProductSprint Backlog'!$I11=D$2), 'ProductSprint Backlog'!$F11, TRUE, 0)} -> 0 | E11: {=_xlfn.IFS('ProductSprint Backlog'!$F11="", "", AND('ProductSprint Backlog'!$J11>E$2,'ProductSprint Backlog'!$I11<=E$2), 'ProductSprint Backlog'!$F11 / MAX(1, 'ProductSprint Backlog'!$J11-'ProductSprint Backlog'!$I11), AND('ProductSprint Backlog'!$J11=E$2,'ProductSprint Backlog'!$I11=E$2), 'ProductSprint Backlog'!$F11, TRUE, 0)} -> 0 | F11: {=_xlfn.IFS('ProductSprint Backlog'!$F11="", "", AND('ProductSprint Backlog'!$J11>F$2,'ProductSprint Backlog'!$I11<=F$2), 'ProductSprint Backlog'!$F11 / MAX(1, 'ProductSprint Backlog'!$J11-'ProductSprint Backlog'!$I11), AND('ProductSprint Backlog'!$J11=F$2,'ProductSprint Backlog'!$I11=F$2), 'ProductSprint Backlog'!$F11, TRUE, 0)} -> 0 | G11: {=_xlfn.IFS('ProductSprint Backlog'!$F11="", "", AND('ProductSprint Backlog'!$J11>G$2,'ProductSprint Backlog'!$I11<=G$2), 'ProductSprint Backlog'!$F11 / MAX(1, 'ProductSprint Backlog'!$J11-'ProductSprint Backlog'!$I11), AND('ProductSprint Backlog'!$J11=G$2,'ProductSprint Backlog'!$I11=G$2), 'ProductSprint Backlog'!$F11, TRUE, 0)} -> 0 | H11: {=_xlfn.IFS('ProductSprint Backlog'!$F11="", "", AND('ProductSprint Backlog'!$J11>H$2,'ProductSprint Backlog'!$I11<=H$2), 'ProductSprint Backlog'!$F11 / MAX(1, 'ProductSprint Backlog'!$J11-'ProductSprint Backlog'!$I11), AND('ProductSprint Backlog'!$J11=H$2,'ProductSprint Backlog'!$I11=H$2), 'ProductSprint Backlog'!$F11, TRUE, 0)} -> 0 | I11: {=_xlfn.IFS('ProductSprint Backlog'!$F11="", "", AND('ProductSprint Backlog'!$J11>I$2,'ProductSprint Backlog'!$I11<=I$2), 'ProductSprint Backlog'!$F11 / MAX(1, 'ProductSprint Backlog'!$J11-'ProductSprint Backlog'!$I11), AND('ProductSprint Backlog'!$J11=I$2,'ProductSprint Backlog'!$I11=I$2), 'ProductSprint Backlog'!$F11, TRUE, 0)} -> 0 | J11: {=_xlfn.IFS('ProductSprint Backlog'!$F11="", "", AND('ProductSprint Backlog'!$J11>J$2,'ProductSprint Backlog'!$I11<=J$2), 'ProductSprint Backlog'!$F11 / MAX(1, 'ProductSprint Backlog'!$J11-'ProductSprint Backlog'!$I11), AND('ProductSprint Backlog'!$J11=J$2,'ProductSprint Backlog'!$I11=J$2), 'ProductSprint Backlog'!$F11, TRUE, 0)} -> 0
B12: {=_xlfn.IFS('ProductSprint Backlog'!$F12="", "", AND('ProductSprint Backlog'!$J12>B$2,'ProductSprint Backlog'!$I12<=B$2), 'ProductSprint Backlog'!$F12 / MAX(1, 'ProductSprint Backlog'!$J12-'ProductSprint Backlog'!$I12), AND('ProductSprint Backlog'!$J12=B$2,'ProductSprint Backlog'!$I12=B$2), 'ProductSprint Backlog'!$F12, TRUE, 0)} -> 0 | C12: {=_xlfn.IFS('ProductSprint Backlog'!$F12="", "", AND('ProductSprint Backlog'!$J12>C$2,'ProductSprint Backlog'!$I12<=C$2), 'ProductSprint Backlog'!$F12 / MAX(1, 'ProductSprint Backlog'!$J12-'ProductSprint Backlog'!$I12), AND('ProductSprint Backlog'!$J12=C$2,'ProductSprint Backlog'!$I12=C$2), 'ProductSprint Backlog'!$F12, TRUE, 0)} -> 0 | D12: {=_xlfn.IFS('ProductSprint Backlog'!$F12="", "", AND('ProductSprint Backlog'!$J12>D$2,'ProductSprint Backlog'!$I12<=D$2), 'ProductSprint Backlog'!$F12 / MAX(1, 'ProductSprint Backlog'!$J12-'ProductSprint Backlog'!$I12), AND('ProductSprint Backlog'!$J12=D$2,'ProductSprint Backlog'!$I12=D$2), 'ProductSprint Backlog'!$F12, TRUE, 0)} -> 0 | E12: {=_xlfn.IFS('ProductSprint Backlog'!$F12="", "", AND('ProductSprint Backlog'!$J12>E$2,'ProductSprint Backlog'!$I12<=E$2), 'ProductSprint Backlog'!$F12 / MAX(1, 'ProductSprint Backlog'!$J12-'ProductSprint Backlog'!$I12), AND('ProductSprint Backlog'!$J12=E$2,'ProductSprint Backlog'!$I12=E$2), 'ProductSprint Backlog'!$F12, TRUE, 0)} -> 0 | F12: {=_xlfn.IFS('ProductSprint Backlog'!$F12="", "", AND('ProductSprint Backlog'!$J12>F$2,'ProductSprint Backlog'!$I12<=F$2), 'ProductSprint Backlog'!$F12 / MAX(1, 'ProductSprint Backlog'!$J12-'ProductSprint Backlog'!$I12), AND('ProductSprint Backlog'!$J12=F$2,'ProductSprint Backlog'!$I12=F$2), 'ProductSprint Backlog'!$F12, TRUE, 0)} -> 0 | G12: {=_xlfn.IFS('ProductSprint Backlog'!$F12="", "", AND('ProductSprint Backlog'!$J12>G$2,'ProductSprint Backlog'!$I12<=G$2), 'ProductSprint Backlog'!$F12 / MAX(1, 'ProductSprint Backlog'!$J12-'ProductSprint Backlog'!$I12), AND('ProductSprint Backlog'!$J12=G$2,'ProductSprint Backlog'!$I12=G$2), 'ProductSprint Backlog'!$F12, TRUE, 0)} -> 0 | H12: {=_xlfn.IFS('ProductSprint Backlog'!$F12="", "", AND('ProductSprint Backlog'!$J12>H$2,'ProductSprint Backlog'!$I12<=H$2), 'ProductSprint Backlog'!$F12 / MAX(1, 'ProductSprint Backlog'!$J12-'ProductSprint Backlog'!$I12), AND('ProductSprint Backlog'!$J12=H$2,'ProductSprint Backlog'!$I12=H$2), 'ProductSprint Backlog'!$F12, TRUE, 0)} -> 0 | I12: {=_xlfn.IFS('ProductSprint Backlog'!$F12="", "", AND('ProductSprint Backlog'!$J12>I$2,'ProductSprint Backlog'!$I12<=I$2), 'ProductSprint Backlog'!$F12 / MAX(1, 'ProductSprint Backlog'!$J12-'ProductSprint Backlog'!$I12), AND('ProductSprint Backlog'!$J12=I$2,'ProductSprint Backlog'!$I12=I$2), 'ProductSprint Backlog'!$F12, TRUE, 0)} -> 0 | J12: {=_xlfn.IFS('ProductSprint Backlog'!$F12="", "", AND('ProductSprint Backlog'!$J12>J$2,'ProductSprint Backlog'!$I12<=J$2), 'ProductSprint Backlog'!$F12 / MAX(1, 'ProductSprint Backlog'!$J12-'ProductSprint Backlog'!$I12), AND('ProductSprint Backlog'!$J12=J$2,'ProductSprint Backlog'!$I12=J$2), 'ProductSprint Backlog'!$F12, TRUE, 0)} -> 0
B13: {=_xlfn.IFS('ProductSprint Backlog'!$F13="", "", AND('ProductSprint Backlog'!$J13>B$2,'ProductSprint Backlog'!$I13<=B$2), 'ProductSprint Backlog'!$F13 / MAX(1, 'ProductSprint Backlog'!$J13-'ProductSprint Backlog'!$I13), AND('ProductSprint Backlog'!$J13=B$2,'ProductSprint Backlog'!$I13=B$2), 'ProductSprint Backlog'!$F13, TRUE, 0)} | C13: {=_xlfn.IFS('ProductSprint Backlog'!$F13="", "", AND('ProductSprint Backlog'!$J13>C$2,'ProductSprint Backlog'!$I13<=C$2), 'ProductSprint Backlog'!$F13 / MAX(1, 'ProductSprint Backlog'!$J13-'ProductSprint Backlog'!$I13), AND('ProductSprint Backlog'!$J13=C$2,'ProductSprint Backlog'!$I13=C$2), 'ProductSprint Backlog'!$F13, TRUE, 0)} | D13: {=_xlfn.IFS('ProductSprint Backlog'!$F13="", "", AND('ProductSprint Backlog'!$J13>D$2,'ProductSprint Backlog'!$I13<=D$2), 'ProductSprint Backlog'!$F13 / MAX(1, 'ProductSprint Backlog'!$J13-'ProductSprint Backlog'!$I13), AND('ProductSprint Backlog'!$J13=D$2,'ProductSprint Backlog'!$I13=D$2), 'ProductSprint Backlog'!$F13, TRUE, 0)} | E13: {=_xlfn.IFS('ProductSprint Backlog'!$F13="", "", AND('ProductSprint Backlog'!$J13>E$2,'ProductSprint Backlog'!$I13<=E$2), 'ProductSprint Backlog'!$F13 / MAX(1, 'ProductSprint Backlog'!$J13-'ProductSprint Backlog'!$I13), AND('ProductSprint Backlog'!$J13=E$2,'ProductSprint Backlog'!$I13=E$2), 'ProductSprint Backlog'!$F13, TRUE, 0)} | F13: {=_xlfn.IFS('ProductSprint Backlog'!$F13="", "", AND('ProductSprint Backlog'!$J13>F$2,'ProductSprint Backlog'!$I13<=F$2), 'ProductSprint Backlog'!$F13 / MAX(1, 'ProductSprint Backlog'!$J13-'ProductSprint Backlog'!$I13), AND('ProductSprint Backlog'!$J13=F$2,'ProductSprint Backlog'!$I13=F$2), 'ProductSprint Backlog'!$F13, TRUE, 0)} | G13: {=_xlfn.IFS('ProductSprint Backlog'!$F13="", "", AND('ProductSprint Backlog'!$J13>G$2,'ProductSprint Backlog'!$I13<=G$2), 'ProductSprint Backlog'!$F13 / MAX(1, 'ProductSprint Backlog'!$J13-'ProductSprint Backlog'!$I13), AND('ProductSprint Backlog'!$J13=G$2,'ProductSprint Backlog'!$I13=G$2), 'ProductSprint Backlog'!$F13, TRUE, 0)} | H13: {=_xlfn.IFS('ProductSprint Backlog'!$F13="", "", AND('ProductSprint Backlog'!$J13>H$2,'ProductSprint Backlog'!$I13<=H$2), 'ProductSprint Backlog'!$F13 / MAX(1, 'ProductSprint Backlog'!$J13-'ProductSprint Backlog'!$I13), AND('ProductSprint Backlog'!$J13=H$2,'ProductSprint Backlog'!$I13=H$2), 'ProductSprint Backlog'!$F13, TRUE, 0)} | I13: {=_xlfn.IFS('ProductSprint Backlog'!$F13="", "", AND('ProductSprint Backlog'!$J13>I$2,'ProductSprint Backlog'!$I13<=I$2), 'ProductSprint Backlog'!$F13 / MAX(1, 'ProductSprint Backlog'!$J13-'ProductSprint Backlog'!$I13), AND('ProductSprint Backlog'!$J13=I$2,'ProductSprint Backlog'!$I13=I$2), 'ProductSprint Backlog'!$F13, TRUE, 0)} | J13: {=_xlfn.IFS('ProductSprint Backlog'!$F13="", "", AND('ProductSprint Backlog'!$J13>J$2,'ProductSprint Backlog'!$I13<=J$2), 'ProductSprint Backlog'!$F13 / MAX(1, 'ProductSprint Backlog'!$J13-'ProductSprint Backlog'!$I13), AND('ProductSprint Backlog'!$J13=J$2,'ProductSprint Backlog'!$I13=J$2), 'ProductSprint Backlog'!$F13, TRUE, 0)}
B14: {=_xlfn.IFS('ProductSprint Backlog'!$F14="", "", AND('ProductSprint Backlog'!$J14>B$2,'ProductSprint Backlog'!$I14<=B$2), 'ProductSprint Backlog'!$F14 / MAX(1, 'ProductSprint Backlog'!$J14-'ProductSprint Backlog'!$I14), AND('ProductSprint Backlog'!$J14=B$2,'ProductSprint Backlog'!$I14=B$2), 'ProductSprint Backlog'!$F14, TRUE, 0)} -> 0 | C14: {=_xlfn.IFS('ProductSprint Backlog'!$F14="", "", AND('ProductSprint Backlog'!$J14>C$2,'ProductSprint Backlog'!$I14<=C$2), 'ProductSprint Backlog'!$F14 / MAX(1, 'ProductSprint Backlog'!$J14-'ProductSprint Backlog'!$I14), AND('ProductSprint Backlog'!$J14=C$2,'ProductSprint Backlog'!$I14=C$2), 'ProductSprint Backlog'!$F14, TRUE, 0)} -> 0 | D14: {=_xlfn.IFS('ProductSprint Backlog'!$F14="", "", AND('ProductSprint Backlog'!$J14>D$2,'ProductSprint Backlog'!$I14<=D$2), 'ProductSprint Backlog'!$F14 / MAX(1, 'ProductSprint Backlog'!$J14-'ProductSprint Backlog'!$I14), AND('ProductSprint Backlog'!$J14=D$2,'ProductSprint Backlog'!$I14=D$2), 'ProductSprint Backlog'!$F14, TRUE, 0)} -> 0 | E14: {=_xlfn.IFS('ProductSprint Backlog'!$F14="", "", AND('ProductSprint Backlog'!$J14>E$2,'ProductSprint Backlog'!$I14<=E$2), 'ProductSprint Backlog'!$F14 / MAX(1, 'ProductSprint Backlog'!$J14-'ProductSprint Backlog'!$I14), AND('ProductSprint Backlog'!$J14=E$2,'ProductSprint Backlog'!$I14=E$2), 'ProductSprint Backlog'!$F14, TRUE, 0)} -> 0 | F14: {=_xlfn.IFS('ProductSprint Backlog'!$F14="", "", AND('ProductSprint Backlog'!$J14>F$2,'ProductSprint Backlog'!$I14<=F$2), 'ProductSprint Backlog'!$F14 / MAX(1, 'ProductSprint Backlog'!$J14-'ProductSprint Backlog'!$I14), AND('ProductSprint Backlog'!$J14=F$2,'ProductSprint Backlog'!$I14=F$2), 'ProductSprint Backlog'!$F14, TRUE, 0)} -> 0 | G14: {=_xlfn.IFS('ProductSprint Backlog'!$F14="", "", AND('ProductSprint Backlog'!$J14>G$2,'ProductSprint Backlog'!$I14<=G$2), 'ProductSprint Backlog'!$F14 / MAX(1, 'ProductSprint Backlog'!$J14-'ProductSprint Backlog'!$I14), AND('ProductSprint Backlog'!$J14=G$2,'ProductSprint Backlog'!$I14=G$2), 'ProductSprint Backlog'!$F14, TRUE, 0)} -> 0 | H14: {=_xlfn.IFS('ProductSprint Backlog'!$F14="", "", AND('ProductSprint Backlog'!$J14>H$2,'ProductSprint Backlog'!$I14<=H$2), 'ProductSprint Backlog'!$F14 / MAX(1, 'ProductSprint Backlog'!$J14-'ProductSprint Backlog'!$I14), AND('ProductSprint Backlog'!$J14=H$2,'ProductSprint Backlog'!$I14=H$2), 'ProductSprint Backlog'!$F14, TRUE, 0)} -> 0 | I14: {=_xlfn.IFS('ProductSprint Backlog'!$F14="", "", AND('ProductSprint Backlog'!$J14>I$2,'ProductSprint Backlog'!$I14<=I$2), 'ProductSprint Backlog'!$F14 / MAX(1, 'ProductSprint Backlog'!$J14-'ProductSprint Backlog'!$I14), AND('ProductSprint Backlog'!$J14=I$2,'ProductSprint Backlog'!$I14=I$2), 'ProductSprint Backlog'!$F14, TRUE, 0)} -> 0 | J14: {=_xlfn.IFS('ProductSprint Backlog'!$F14="", "", AND('ProductSprint Backlog'!$J14>J$2,'ProductSprint Backlog'!$I14<=J$2), 'ProductSprint Backlog'!$F14 / MAX(1, 'ProductSprint Backlog'!$J14-'ProductSprint Backlog'!$I14), AND('ProductSprint Backlog'!$J14=J$2,'ProductSprint Backlog'!$I14=J$2), 'ProductSprint Backlog'!$F14, TRUE, 0)} -> 0
